<robot name="ADAM" xmlns:xacro="http://www.ros.org/wiki/xacro">

  <xacro:property name="pi" value="3.141594" />
  <xacro:property name="wheel_base_width" value="0.2" />
  <xacro:property name="channel_width" value="0.03" />
  <xacro:property name="tread_thickness" value="0.08" />
  <xacro:property name="motor_length" value="0.065" />
  <xacro:property name="motor_radius" value="0.02" />
  <xacro:property name="black_plastic_thickness" value="0.005" />
  <xacro:property name="axle_length" value="0.03" />
  

  <!-- fixed by meshes (do not change) -->
  <xacro:property name="passive_wheel_radius" value=".03" />

  
  <material name="black">
    <color rgba="0 0 0 1"/>
  </material>

  <material name="white">
    <color rgba="1 1 1 1"/>
  </material>

  <material name="gray">
    <color rgba="0.5 0.5 0.5 1"/>
  </material>

  <xacro:macro name="default_inertial" params="mass">
    <inertial>
      <mass value="${mass}" />
      <inertia ixx="1.0" ixy="0.0" ixz="0.0" iyy="1.0" iyz="0.0" izz="1.0" />
    </inertial>
  </xacro:macro>


  <!-- Chassis -->

  <link name="base_link">
    <visual>
      <geometry>
        <box size="0.16 ${channel_width} ${channel_width}"/>
      </geometry>
      <origin rpy="0 0 0" xyz="0 0.03 ${channel_width}"/>
      <material name="white"/>
    </visual>
  </link>


  <link name="left_base">
    <visual>
      <geometry>
        <box size="0.29 ${channel_width} ${channel_width}"/>
      </geometry>
      <material name="white"/>
    </visual>
  </link>

  <joint name="left_base_to_front_base" type="fixed">
    <axis xyz="0 0 0" rpy="0 0 0" />
    <parent link="base_link"/>
    <child link="left_base"/>
    <origin xyz="0.064 0 0" rpy="0 0 ${pi/2}"/>
  </joint> 


  <link name="right_base">
    <visual>
      <geometry>
        <box size="0.29 ${channel_width} ${channel_width}"/>
      </geometry>
      <material name="white"/>
    </visual>
  </link>

  <joint name="right_base_to_front_base" type="fixed">
    <axis xyz="0 0 0" rpy="0 0 0" />
    <parent link="base_link"/>
    <child link="right_base"/>
    <origin xyz="-0.064 0 0" rpy="0 0 ${pi/2}"/>
  </joint> 

  <link name="rear_base">
    <visual>
      <geometry>
        <box size="0.16 ${channel_width} ${channel_width}"/>
      </geometry>
      <material name="white"/>
    </visual>
  </link>

  <joint name="rear_base_to_front_base" type="fixed">
    <axis xyz="0 0 0" rpy="0 0 0" />
    <parent link="base_link"/>
    <child link="rear_base"/>
    <origin xyz="0 -0.1 ${channel_width}" rpy="0 0 0"/>
  </joint> 


  <link name="black_plastic_base">
    <visual>
      <geometry>
        <box size="0.16 0.2 ${black_plastic_thickness}"/>
        <origin xyz="0 0 ${black_plastic_thickness/2}" rpy="0 0 0"/>
      </geometry>
      <material name="black"/>
    </visual>
  </link>

  <joint name="black_plastic_base_to_front_base" type="fixed">
    <axis xyz="0 0 0" rpy="0 0 0" />
    <parent link="base_link"/>
    <child link="black_plastic_base"/>
    <origin xyz="0 -0.02 ${1.5*channel_width}" rpy="0 0 0"/>
  </joint> 



  <!-- Passive (black) Wheels -->
  <xacro:macro name="wheel" params="prefix suffix x y">
      <link name="${prefix}_${suffix}_wheel">
        <visual>
          <origin xyz="0 0 ${passive_wheel_radius}" rpy="0 ${pi/2} 0" />
          <geometry>
            <mesh filename="package://adam_description/meshes/passive_wheel.dae"/>
          </geometry>
          <material name="light_gray">
            <color rgba="0 0 0 1"/>
          </material>
        </visual>
        <collision>
          <origin xyz="0 0 ${passive_wheel_radius}" rpy="0 ${pi/2} 0" />
          <geometry>
            <mesh filename="package://adam_description/meshes/passive_wheel.dae"/>
          </geometry>
        </collision>
        <xacro:default_inertial mass="1"/>
      </link>

      <joint name="${prefix}_${suffix}_wheel_joint" type="continuous">
        <axis xyz="1 0 0" rpy="0 ${pi/2} 0" />
        <parent link="base_link"/>
        <child link="${prefix}_${suffix}_wheel"/>
        <origin xyz="${x} ${y} ${-channel_width}" rpy="0 0 0"/>
      </joint> 
  </xacro:macro>


  <xacro:wheel prefix="front" suffix="right" x="${wheel_base_width/2}" y="0.128"/>
  <xacro:wheel prefix="center" suffix="right" x="${wheel_base_width/2}" y="0"/>
  <xacro:wheel prefix="rear" suffix="right"  x="${wheel_base_width/2}" y="-0.128"/>
  <xacro:wheel prefix="front" suffix="left" x="${-wheel_base_width/2}" y="0.128"/>
  <xacro:wheel prefix="center" suffix="left" x="${-wheel_base_width/2}" y="0"/>
  <xacro:wheel prefix="rear" suffix="left"  x="${-wheel_base_width/2}" y="-0.128"/>


  <!-- Motors -->

  <link name="right_motor">
    <visual>
      <geometry>
        <cylinder length="0.065" radius="0.02"/>
      </geometry>
      <material name="gray">
        <color rgba="0.3 0.3 0.3 1"/>
      </material>
    </visual>
  </link>

  <joint name="right_motor_to_base" type="fixed">
    <parent link="base_link"/>
    <child link="right_motor"/>
    <origin rpy="0 1.57075 0" xyz="0.045 0 ${1.5*channel_width + black_plastic_thickness + 0.021}"/>
  </joint>

  <link name="left_motor">
    <visual>
      <geometry>
        <cylinder length="${motor_length}" radius="${motor_radius}"/>
      </geometry>
      <material name="gray">
        <color rgba="0.3 0.3 0.3 1"/>
      </material>
    </visual>
  </link>

  <joint name="left_motor_to_base" type="fixed">
    <parent link="base_link"/>
    <child link="left_motor"/>
    <origin rpy="0 1.57075 0" xyz="-0.045 0 ${1.5*channel_width + black_plastic_thickness + 0.021}"/>
  </joint>


  <link name="left_axle">
    <visual>
      <geometry>
        <cylinder length="${axle_length}" radius="0.0025"/>
      </geometry>
      <material name="gray">
        <color rgba="0.3 0.3 0.3 1"/>
      </material>
    </visual>
  </link>

  <joint name="left_axle_to_motor" type="continuous">
    <parent link="left_motor"/>
    <child link="left_axle"/>
    <origin xyz="0 0 ${-motor_length/2}"/>
  </joint>
  
  <link name="right_axle">
    <visual>
      <geometry>
        <cylinder length="${axle_length}" radius="0.0025"/>
      </geometry>
      <material name="gray">
        <color rgba="0.3 0.3 0.3 1"/>
      </material>
    </visual>
  </link>

  <joint name="right_axle_to_motor" type="continuous">
    <parent link="right_motor"/>
    <child link="right_axle"/>
    <origin xyz="0 0 ${motor_length/2}"/>
  </joint>
  

<!-- Active Wheels -->

  <link name="right_active_wheel">
    <visual>
      <geometry>
        <cylinder length="0.008" radius="0.0325"/>
      </geometry>
      <material name="white">
        <color rgba="1 1 1 1"/>
      </material>
    </visual>
  </link>

  <joint name="right_active_wheel_to_axle" type="fixed">
    <parent link="right_axle"/>
    <child link="right_active_wheel"/>
    <origin xyz="0 0 0.02"/>
  </joint>
  
<link name="left_active_wheel">
    <visual>
      <geometry>
        <cylinder length="0.008" radius="0.0325"/>
      </geometry>
      <material name="white">
        <color rgba="1 1 1 1"/>
      </material>
    </visual>
  </link>

  <joint name="left_active_wheel_to_axle" type="fixed">
    <parent link="left_axle"/>
    <child link="left_active_wheel"/>
    <origin xyz="0 0 -0.02"/>
  </joint>
  

<!-- Ultrasonic Sensors -->
  
  <xacro:macro name="ultrasonic_sensor" params="prefix suffix x y z thetaz thetax">
      <link name="${prefix}_${suffix}_ultrasonic_sensor">
        <visual>
          <geometry>
            <mesh filename="package://adam_description/meshes/ultrasonic_sensor_with_mount.dae"/>
          </geometry>
        </visual>
        <collision>
          <geometry>
            <mesh filename="package://adam_description/meshes/ultrasonic_sensor_with_mount.dae"/>
          </geometry>
        </collision>
        <xacro:default_inertial mass="1"/>
      </link>

      <joint name="${prefix}_${suffix}_ultrasonic_sensor_mount" type="fixed">
        <axis xyz="0 0 0" rpy="0 0 0" />
        <parent link="base_link"/>
        <child link="${prefix}_${suffix}_ultrasonic_sensor"/>
        <origin xyz="${x} ${y} ${z}" rpy="${thetax} 0 ${thetaz+pi/2}"/>
      </joint> 
  </xacro:macro>

  <xacro:ultrasonic_sensor prefix="front" suffix="center" x="0.0" y="0.05" z="${0.5*channel_width}" thetax="0" thetaz="0"/>
  <xacro:ultrasonic_sensor prefix="front" suffix="right" x="0.02" y="0.05" z="${1.5*channel_width}" thetax="0" thetaz="${-pi/6}"/>
  <xacro:ultrasonic_sensor prefix="front" suffix="left" x="-0.02" y="0.05" z="${1.5*channel_width}" thetax="0" thetaz="${pi/6}"/>
  <xacro:ultrasonic_sensor prefix="rear" suffix="center" x="0.0" y="-0.1" z="${0.5*channel_width}" thetax="0" thetaz="${pi}"/>
  

  <link name="kinect">
    <visual>
      <geometry>
        <mesh filename="package://adam_description/meshes/kinect.dae"/>
      </geometry>
      <material name="black">
        <color rgba="0 0 0 1"/>
      </material>
    </visual>
    <collision>
      <geometry>
        <mesh filename="package://adam_description/meshes/kinect.dae"/>
      </geometry>
    </collision>
  </link>

  <joint name="kinect_to_base" type="fixed">
    <axis xyz="0 0 0" rpy="0 0 0" />
    <parent link="base_link"/>
    <child link="kinect"/>
    <origin xyz="0 0 0.2" rpy="0 0 0"/>
  </joint> 

  <link name="kinect_sensor">
    <geometry>
      <box size="0.01 0.01 0.01"/>
      <origin xyz="0 0 0" rpy="0 0 0"/>
    </geometry>
  </link> 

  <joint name="kinect_sensor_to_kinect" type="fixed">
    <parent link="kinect"/>
    <child link="kinect_sensor"/>
    <origin xyz="0 0 0" rpy="1.57075 3.14159 0"/>
  </joint> 

</robot>
