<?xml version="1.0"?>
<robot name="ADAM">


  <!-- Base, Risers, Drawer (first level) -->

  <link name="base_link">
    <visual>
      <geometry>
        <mesh filename="file:///home/brian/robotics_code/ROS/ADAM_description/meshes/adam_base.dae"/>
      </geometry>
      <material name="white">
         <color rgba="1 1 1 1"/>
      </material>
    </visual>
  </link>

  <link name="right_riser_level1">
    <visual>
      <geometry>
        <box size="0.0075 0.165 0.07"/>
      </geometry>
      <material name="white">
         <color rgba="1 1 1 1"/>
      </material>
    </visual>
  </link>
  <joint name="base_to_right_riser_level1" type="fixed">
    <parent link="base_link"/>
    <child link="right_riser_level1"/>
    <origin xyz="0.0725 -0.0625 0.035"/>
  </joint>


  <link name="left_riser_level1">
    <visual>
      <geometry>
        <box size="0.0075 0.165 0.07"/>
      </geometry>
      <material name="white">
         <color rgba="1 1 1 1"/>
      </material>
    </visual>
  </link>
  <joint name="base_to_left_riser_level1" type="fixed">
    <parent link="base_link"/>
    <child link="left_riser_level1"/>
    <origin xyz="-0.0725 -0.0625 0.035"/>
  </joint>


  <link name="drawer">
    <visual>
      <geometry>
        <box size="0.14 0.14 0.005"/>
      </geometry>
      <material name="white">
         <color rgba="1 1 1 1"/>
      </material>
    </visual>
  </link>
  <joint name="base_to_drawer" type="fixed">
    <parent link="base_link"/>
    <child link="drawer"/>
    <origin xyz="0 -0.065 0.0075"/>
  </joint>


  <!-- Motors, Wheels, Axles -->

  <link name="right_motor">
    <visual>
      <geometry>
        <cylinder length="0.07" radius="0.02"/>
      </geometry>
      <material name="light_gray">
        <color rgba="0.3 0.3 0.3 1"/>
      </material>
    </visual>
  </link>
  <joint name="right_motor_to_base" type="fixed">
    <parent link="base_link"/>
    <child link="right_motor"/>
    <origin rpy="0 1.57075 0" xyz="0.075 0 -.03"/>
  </joint>

   <link name="right_axle">
    <visual>
      <geometry>
        <cylinder length="0.02" radius="0.0025"/>
      </geometry>
      <material name="light_gray">
        <color rgba="1.0 0.3 0.3 1"/>
      </material>
    </visual>
  </link>
  <joint name="right_axle_to_motor" type="continuous">
    <parent link="right_motor"/>
    <child link="right_axle"/>
    <axis xyz="0 0 1"/>
    <origin rpy="0 0 0" xyz="0.0 0 0.045"/>
  </joint>

  <link name="right_wheel">
    <visual>
      <geometry>
        <mesh filename="file:///home/brian/robotics_code/ROS/ADAM_description/meshes/wheel_90mm.dae"/>
      </geometry>
      <material name="dark_Gray">
         <color rgba="0 0 0 1"/>
      </material>
    </visual>
  </link>
  <joint name="right_wheel_to_axle" type="fixed">
    <parent link="right_axle"/>
    <child link="right_wheel"/>
    <origin rpy="0 0 0" xyz="0 0 0.015"/>
  </joint>


  <link name="left_motor">
    <visual>
      <geometry>
        <cylinder length="0.07" radius="0.02"/>
      </geometry>
      <material name="light_gray">
        <color rgba="0.3 0.3 0.3 1"/>
      </material>
    </visual>
  </link>
  <joint name="left_motor_to_base" type="fixed">
    <parent link="base_link"/>
    <child link="left_motor"/>
    <origin rpy="0 -1.57075 0" xyz="-0.075 0 -.03"/>
  </joint>

   <link name="left_axle">
    <visual>
      <geometry>
        <cylinder length="0.03" radius="0.0025"/>
      </geometry>
      <material name="light_gray">
        <color rgba="1.0 0.3 0.3 1"/>
      </material>
    </visual>
  </link>
  <joint name="left_axle_to_motor" type="continuous">
    <parent link="left_motor"/>
    <child link="left_axle"/>
    <axis xyz="0 0 1"/>
    <origin rpy="0 0 0" xyz="0.0 0 0.045"/>
  </joint>

  <link name="left_wheel">
    <visual>
      <geometry>
        <mesh filename="file:///home/brian/robotics_code/ROS/ADAM_description/meshes/wheel_90mm.dae"/>
      </geometry>
      <material name="dark_Gray">
         <color rgba="0.1 0.1 0.1 1"/>
      </material>
    </visual>
  </link>
  <joint name="left_wheel_to_axle" type="fixed">
    <parent link="left_axle"/>
    <child link="left_wheel"/>
    <origin rpy="0 0 0" xyz="0 0 0.015"/>
  </joint>


  <link name="castor_pivot">
    <visual>
      <geometry>
        <cylinder length="0.005" radius="0.015"/>
      </geometry>
      <material name="gray">
         <color rgba="0.4 0.4 0.4 1"/>
      </material>
    </visual>
  </link>
  <joint name="base_to_caster_pivot" type="continuous">
    <parent link="base_link"/>
    <child link="castor_pivot"/>
    <axis xyz="0 0 1"/>
    <origin xyz="0 -0.19 -0.0115"/>
  </joint>


  <link name="castor_wheel">
    <visual>
      <geometry>
        <cylinder length="0.014" radius="0.015"/>
      </geometry>
      <material name="black">
         <color rgba="0.1 0.1 0.1 1"/>
      </material>
    </visual>
  </link>
  <joint name="caster_pivot_to_caster_wheel" type="continuous">
    <parent link="castor_pivot"/>
    <child link="castor_wheel"/>
    <axis xyz="0 0 1"/>
    <origin rpy="0 1.57075 0" xyz="0 -0.012 -0.02"/>
  </joint>


  <!-- Ultrasonic Sensors -->

  <link name="front_center_ultrasonic_sensor">
    <visual>
      <geometry>
        <mesh filename="file:///home/brian/robotics_code/ROS/ADAM_description/meshes/ultrasonic_sensor_with_mount.dae"/>
      </geometry>
    </visual>
  </link>
  <joint name="base_to_front_center_ultrasonic_sensor" type="fixed">
    <parent link="base_link"/>
    <child link="front_center_ultrasonic_sensor"/>
    <origin rpy="0 0 0" xyz="0 0 0"/>
  </joint>

  <link name="front_right_ultrasonic_sensor">
    <visual>
      <geometry>
        <mesh filename="file:///home/brian/robotics_code/ROS/ADAM_description/meshes/ultrasonic_sensor_with_mount.dae"/>
      </geometry>
    </visual>
  </link>
  <joint name="base_to_front_right_ultrasonic_sensor" type="fixed">
    <parent link="base_link"/>
    <child link="front_right_ultrasonic_sensor"/>
    <origin rpy="0 0 -0.523" xyz="0.09 0 0"/>
  </joint>

  <link name="front_left_ultrasonic_sensor">
    <visual>
      <geometry>
        <mesh filename="file:///home/brian/robotics_code/ROS/ADAM_description/meshes/ultrasonic_sensor_with_mount.dae"/>
      </geometry>
    </visual>
  </link>
  <joint name="base_to_front_left_ultrasonic_sensor" type="fixed">
    <parent link="base_link"/>
    <child link="front_left_ultrasonic_sensor"/>
    <origin rpy="0 0 0.523" xyz="-0.09 0 0"/>
  </joint>

  <link name="rear_center_ultrasonic_sensor">
    <visual>
      <geometry>
        <mesh filename="file:///home/brian/robotics_code/ROS/ADAM_description/meshes/ultrasonic_sensor_with_mount.dae"/>
      </geometry>
    </visual>
  </link>
  <joint name="base_to_rear_center_ultrasonic_sensor" type="fixed">
    <parent link="base_link"/>
    <child link="rear_center_ultrasonic_sensor"/>
    <origin rpy="0 0 3.1415" xyz="0 -0.20 0"/>
  </joint>

  <link name="rear_right_ultrasonic_sensor">
    <visual>
      <geometry>
        <mesh filename="file:///home/brian/robotics_code/ROS/ADAM_description/meshes/ultrasonic_sensor_with_mount.dae"/>
      </geometry>
    </visual>
  </link>
  <joint name="base_to_rear_right_ultrasonic_sensor" type="fixed">
    <parent link="base_link"/>
    <child link="rear_right_ultrasonic_sensor"/>
    <origin rpy="0 0 -2.36" xyz="0.06 -0.16 0"/>
  </joint>

  <link name="rear_left_ultrasonic_sensor">
    <visual>
      <geometry>
        <mesh filename="file:///./meshes/ultrasonic_sensor_with_mount.dae"/>
      </geometry>
    </visual>
  </link>
  <joint name="base_to_rear_left_ultrasonic_sensor" type="fixed">
    <parent link="base_link"/>
    <child link="rear_left_ultrasonic_sensor"/>
    <origin rpy="0 0 2.36" xyz="-0.06 -0.16 0"/>
  </joint>


  <!-- Kinect -->

  <link name="kinect">
    <visual>
      <geometry>
        <mesh filename="file:///home/brian/robotics_code/ROS/ADAM_description/meshes/kinect.dae"/>
      </geometry>
    </visual>
  </link>
  <joint name="base_to_kinect" type="fixed">
    <parent link="base_link"/>
    <child link="kinect"/>
    <origin rpy="0 0 3.141593" xyz="0 -.05 .10"/>
  </joint>
  
  <!--
  <gazebo reference="kinect">
    <plugin name="kinect_controller" filename="libgazebo_ros_openni_kinect.so">
      <baseline>0.2</baseline>
      <alwaysOn>true</alwaysOn>
      <updateRate>1.0</updateRate>
      <cameraName>kinect</cameraName>
      <imageTopicName>//depth/image_raw</imageTopicName>
      <cameraInfoTopicName>/${camera_name}/depth/camera_info</cameraInfoTopicName>
      <depthImageTopicName>/${camera_name}/depth/image_raw</depthImageTopicName>
      <depthImageInfoTopicName>/${camera_name}/depth/camera_info</depthImageInfoTopicName>
      <pointCloudTopicName>/${camera_name}/depth/points</pointCloudTopicName>
      <frameName>kinect</frameName>
      <pointCloudCutoff>0.5</pointCloudCutoff>
      <distortionK1>0.00000001</distortionK1>
      <distortionK2>0.00000001</distortionK2>
      <distortionK3>0.00000001</distortionK3>
      <distortionT1>0.00000001</distortionT1>
      <distortionT2>0.00000001</distortionT2>
      <CxPrime>0</CxPrime>
      <Cx>0</Cx>
      <Cy>0</Cy>
      <focalLength>0</focalLength>
      <hackBaseline>0</hackBaseline>
    </plugin>
  </gazebo>
  -->

</robot>
